{"name": "test_04", "status": "failed", "statusDetails": {"message": "AssertionError: assert 2 == 3", "trace": "def test_04():\n    \n    # 实际结果在前面   ，预期结果在后面\n>       assert 2 ==3\nE       assert 2 == 3\n\ntest_assert.py:39: AssertionError"}, "start": 1666798540184, "stop": 1666798540184, "uuid": "25a46d84-8df7-4098-90cc-c4f1f359da8d", "historyId": "44ed123505ba1bb4ae9310e510acc117", "testCaseId": "f05a09a5063fc00b43298302e16f24ee", "fullName": "test_assert#test_04", "labels": [{"name": "suite", "value": "test_assert"}, {"name": "host", "value": "LAPTOP-GID304T1"}, {"name": "thread", "value": "11764-MainThread"}, {"name": "framework", "value": "pytest"}, {"name": "language", "value": "cpython3"}, {"name": "package", "value": "test_assert"}]}